Exception calling function - run_model: (ModelServiceException(...), 'Model service error: There is no documents processed for the inference. Check if record is correct\nconcurrent.futures.process._RemoteTraceback: \n"""\nTraceback (most recent call last):\n  File "/opt/python-3.7.7/lib/python3.7/concurrent/futures/process.py", line 239, in _process_worker\n    r = call_item.fn(*call_item.args, **call_item.kwargs)\n  File "/model-service/py/instabase/model_service/model_process.py", line 133, in _run_in_subprocess\n    result = loaded_model.run(request)\n  File "/home/ibuser/models/model_registry/model-model_Finalmodel_c55acf390da94378a26b4a10b0684c79-v0.0.1-OEJFwDQn/model_Finalmodel_c55acf390da94378a26b4a10b0684c79/model.py", line 144, in run\n    raise ValueError("There is no documents processed for the inference. Check if record is correct")\nValueError: There is no documents processed for the inference. Check if record is correct\n"""\n\nThe above exception was the direct cause of the following exception:\n\nTraceback (most recent call last):\n  File "/model-service/py/instabase/model_service/handler.py", line 66, in RunModel\n    model_result = self.model_cache.run_model(request)\n  File "/model-service/py/instabase/model_service/model_cache.py", line 99, in run_model\n    return model.run(request)\n  File "/model-service/py/instabase/model_service/model_process.py", line 63, in run\n    result = future.result(timeout=app_config.MODEL_RUN_TIMEOUT_SECS)\n  File "/opt/python-3.7.7/lib/python3.7/concurrent/futures/_base.py", line 435, in result\n    return self.__get_result()\n  File "/opt/python-3.7.7/lib/python3.7/concurrent/futures/_base.py", line 384, in __get_result\n    raise self._exception\nValueError: There is no documents processed for the inference. Check if record is correct\n (StatusCode.INTERNAL)'). Defined in scripts/run_model.py (line 140)

Traceback:
  File "scripts/run_model.py", line 140, in run_model
  File "ib/market/ib_intelligence/functions.py", line 140, in run_model
  File "/instabase/workers/celery-app-tasks/py/instabase/model_service/sdk.py", line 350, in run_json
    json.dumps(request), model_service_pb2.RunModelRequest())))
  File "/instabase/workers/celery-app-tasks/py/instabase/model_service/sdk.py", line 101, in wrapper
    raise ModelServiceException(e) from None



    This change should go to GIT +++++++++++++++++++++++